<?xml version="1.0" ?>
<sdf version="1.5">
  <model name="rm3_robot">
    <static>false</static>
    <link name="chassis">
      <pose>0 0 0.17 0 0 0</pose>
      <inertial>
        <mass>5.67</mass>
        <inertia>
          <ixx>0.07</ixx>
          <iyy>0.08</iyy>
          <izz>0.10</izz>
          <ixy>0</ixy>
          <ixz>0</ixz>
          <iyz>0</iyz>
        </inertia>
      </inertial>
      <collision name="collision">
        <geometry>
          <box>
            <size>0.8 0.5 0.1</size>
          </box>
        </geometry>
      </collision>
      <collision name="top_collision">
        <pose>0 0 0.075 0 0 0</pose>
        <geometry>
          <box>
            <size>0.8 0.75 0.05</size>
          </box>
        </geometry>
      </collision>
      <collision name="right_castor_collision">
        <pose>-0.25 -0.15 -0.07 0 0 0</pose>
        <geometry>
          <sphere>
            <radius>0.1</radius>
          </sphere>
        </geometry>
        <surface>
          <friction>
            <ode>
              <mu>0</mu>
              <mu2>0</mu2>
              <slip1>1.0</slip1>
              <slip2>1.0</slip2>
            </ode>
          </friction>
        </surface>
      </collision>
      <collision name="left_castor_collision">
        <pose>-0.25 0.15 -0.07 0 0 0</pose>
        <geometry>
          <sphere>
            <radius>0.1</radius>
          </sphere>
        </geometry>
        <surface>
          <friction>
            <ode>
              <mu>0</mu>
              <mu2>0</mu2>
              <slip1>1.0</slip1>
              <slip2>1.0</slip2>
            </ode>
          </friction>
        </surface>
      </collision>
      <visual name="visual">
        <geometry>
          <box>
            <size>0.8 0.5 0.1</size>
          </box>
        </geometry>
        <material> 
            <ambient>0 0.55 0.35 1</ambient>
            <diffuse>0 0.55 0.35 1</diffuse>
            <specular>0 0 0 0</specular>
            <emissive>0 0 0 1</emissive>
        </material>
      </visual>
      <visual name="top_visual">
        <pose>0 0 0.075 0 0 0</pose>
        <geometry>
          <box>
            <size>0.8 0.75 0.05</size>
          </box>
        </geometry>
	<material> 
            <ambient>1 1 0.4 1</ambient>
            <diffuse>1 1 0.4 1</diffuse>
            <specular>0 0 0 0</specular>
            <emissive>0 0 0 1</emissive>
        </material>
      </visual>
      <visual name="right_castor_visual">
        <pose>-0.25 -0.15 -0.07 0 0 0</pose>
        <geometry>
          <sphere>
            <radius>0.1</radius>
          </sphere>
        </geometry>
        <material> 
            <ambient>0.1 0.1 0.1 1</ambient>
            <diffuse>0.1 0.1 0.2 1</diffuse>
            <specular>0 0 0 0</specular>
            <emissive>0 0 0 1</emissive>
        </material>
      </visual>
      <visual name="left_castor_visual">
        <pose>-0.25 0.15 -0.07 0 0 0</pose>
        <geometry>
          <sphere>
            <radius>0.1</radius>
          </sphere>
        </geometry>
        <material> 
            <ambient>0.1 0.1 0.1 1</ambient>
            <diffuse>0.1 0.1 0.2 1</diffuse>
            <specular>0 0 0 0</specular>
            <emissive>0 0 0 1</emissive>
        </material>
      </visual>
    </link>
    <link name="right_wheel">
      <pose>0.25 -0.31 0.1 0 1.5707 1.5707</pose>
      <inertial>
        <mass>1.5</mass>
        <inertia>
          <ixx>0.0051</ixx>
          <iyy>0.0051</iyy>
          <izz>0.0090</izz>
          <ixy>0</ixy>
          <ixz>0</ixz>
          <iyz>0</iyz>
        </inertia>
      </inertial>
      <collision name="collision">
        <geometry>
          <cylinder>
            <radius>0.1</radius>
            <length>0.1</length>
          </cylinder>
        </geometry>
        <surface>
          <friction>
            <ode>
              <mu>1.0</mu>
              <mu2>1.0</mu2>
              <slip1>0.0</slip1>
              <slip2>0.0</slip2>
            </ode>
          </friction>
            <contact>
            <ode>
              <soft_cfm>0</soft_cfm>
              <soft_erp>0.3</soft_erp>
              <kp>1e+10</kp>
              <kd>10</kd>
              <max_vel>1.0</max_vel>
              <min_depth>0.01</min_depth>
            </ode>
          </contact>
        </surface>
      </collision>
      <visual name="visual">
        <geometry>
          <cylinder>
            <radius>0.1</radius>
            <length>0.1</length>
          </cylinder>
        </geometry>
        <material> 
            <ambient>0.1 0.1 0.1 1</ambient>
            <diffuse>0.1 0.1 0.2 1</diffuse>
            <specular>0 0 0 0</specular>
            <emissive>0 0 0 1</emissive>
          </material>
      </visual>

    </link>
    <link name="left_wheel">
      <pose>0.25 0.31 0.1 0 1.5707 1.5707</pose>
      <inertial>
        <mass>1.5</mass>
        <inertia>
          <ixx>0.0051</ixx>
          <iyy>0.0051</iyy>
          <izz>0.0090</izz>
          <ixy>0</ixy>
          <ixz>0</ixz>
          <iyz>0</iyz>
        </inertia>
      </inertial>
      <collision name="collision">
        <geometry>
          <cylinder>
            <radius>0.1</radius>
            <length>0.1</length>
          </cylinder>
        </geometry>
        <surface>
          <friction>
            <ode>
              <mu>1.0</mu>
              <mu2>1.0</mu2>
              <slip1>0.0</slip1>
              <slip2>0.0</slip2>
            </ode>
          </friction>
            <contact>
            <ode>
              <soft_cfm>0</soft_cfm>
              <soft_erp>0.3</soft_erp>
              <kp>1e+10</kp>
              <kd>10</kd>
              <max_vel>1.0</max_vel>
              <min_depth>0.01</min_depth>
            </ode>
          </contact>
        </surface>
      </collision>
      <visual name="visual">
        <geometry>
          <cylinder>
            <radius>0.1</radius>
            <length>0.1</length>
          </cylinder>
        </geometry>
        <material> 
            <ambient>0.1 0.1 0.1 1</ambient>
            <diffuse>0.1 0.1 0.2 1</diffuse>
            <specular>0 0 0 0</specular>
            <emissive>0 0 0 1</emissive>
          </material>
      </visual>
    </link>


    <joint type="revolute" name="left_wheel_hinge">
      <pose>0 0 -0.03 0 0 0</pose>
      <child>left_wheel</child>
      <parent>chassis</parent>
      <axis>
        <xyz>0 1 0</xyz>
        <use_parent_model_frame>true</use_parent_model_frame>
      </axis>
    </joint>
    <joint type="revolute" name="right_wheel_hinge">
      <pose>0 0 0.03 0 0 0</pose>
      <child>right_wheel</child>
      <parent>chassis</parent>
      <axis>
        <xyz>0 1 0</xyz>
        <use_parent_model_frame>true</use_parent_model_frame>
      </axis>
    </joint>


    <plugin name="differential_drive_controller" filename="libgazebo_ros_diff_drive.so">

      <updateRate>10.0</updateRate>
  
      <!-- wheels -->
      <leftJoint>left_wheel_hinge</leftJoint>
      <rightJoint>right_wheel_hinge</rightJoint>

      <!-- kinematics-->
      <wheelSeparation>0.5</wheelSeparation>
      <wheelDiameter>0.2</wheelDiameter>
      <wheelAcceleration>0.0</wheelAcceleration>
      <wheelTorque>2</wheelTorque>

      <!-- Odometry-->
      <commandTopic>cmd_vel</commandTopic>
      <odometryTopic>odom</odometryTopic>
      <odometryFrame>odom</odometryFrame>
      <robotBaseFrame>chassis</robotBaseFrame>
      <odometrySource>world</odometrySource>
      <publishWheelTF>true</publishWheelTF>
      <publishOdom>true</publishOdom>
      <publishWheelJointState>true</publishWheelJointState>
      <legacyMode>false</legacyMode>
      <publishTf>true</publishTf>
      <publishOdomTF>True</publishOdomTF>
      
    </plugin>

    </model>
    
</sdf>